Workbook

Sheet coffee shop project
A1: Transaction_ID | B1: Transaction_Date | C1: Area Code | D1: State | E1: Market | F1: Market Size | G1: Product Line | H1: Product Type | I1: Product | J1: Type | K1: Inventory | L1: Marketing | M1: Sales | N1: Cogs | O1: Total Expenses | P1: Profit | Q1: Profit Margin | R1: Target Sales | S1: Target COGS | T1: Target Profit | U1: Target Profit Margin | V1: Difference Between Actual and Target Profit
A2: TXN-00001 | B2: 45292 | C2: 715 | D2: Wisconsin | E2: Central | F2: Small Market | G2: Leaves | H2: Tea | I2: Darjeeling | J2: Regular | K2: 454 | L2: 15 | M2: 128 | N2: 49 | O2: 38 | P2: 49 | Q2: 0.3828 | R2: 90 | S2: 40 | T2: 20 | U2: 0.2222 | V2: 29
A3: TXN-00002 | B3: 45292 | C3: 719 | D3: Colorado | E3: Central | F3: Major Market | G3: Beans | H3: Coffee | I3: Amaretto | J3: Regular | K3: 959 | L3: 34 | M3: 302 | N3: 123 | O3: 45 | P3: 134 | Q3: 0.4437 | R3: 290 | S3: 120 | T3: 130 | U3: 0.4483 | V3: 4
A4: TXN-00003 | B4: 45292 | C4: 309 | D4: Illinois | E4: Central | F4: Major Market | G4: Leaves | H4: Herbal Tea | I4: Chamomile | J4: Decaf | K4: 959 | L4: 34 | M4: 302 | N4: 123 | O4: 46 | P4: 133 | Q4: 0.4404 | R4: 280 | S4: 110 | T4: 130 | U4: 0.4643 | V4: 3
A5: TXN-00004 | B5: 45293 | C5: 719 | D5: Colorado | E5: Central | F5: Major Market | G5: Leaves | H5: Tea | I5: Earl Grey | J5: Regular | K5: 1042 | L5: 17 | M5: 133 | N5: 57 | O5: 39 | P5: 43 | Q5: 0.3233 | R5: 100 | S5: 40 | T5: 30 | U5: 0.3 | V5: 13
A6: TXN-00005 | B6: 45293 | C6: 505 | D6: New Mexico | E6: South | F6: Small Market | G6: Leaves | H6: Herbal Tea | I6: Lemon | J6: Decaf | K6: 1000 | L6: 9 | M6: 72 | N6: 31 | O6: 31 | P6: 9 | Q6: 0.125 | R6: 50 | S6: 10 | T6: 30 | U6: 0.6 | V6: -21
A7: TXN-00006 | B7: 45294 | C7: 262 | D7: Wisconsin | E7: Central | F7: Small Market | G7: Leaves | H7: Tea | I7: Earl Grey | J7: Regular | K7: 627 | L7: 49 | M7: 140 | N7: 55 | O7: 79 | P7: -4 | Q7: -0.0286 | R7: 100 | S7: 40 | T7: 0 | U7: 0 | V7: -4
A8: TXN-00007 | B8: 45294 | C8: 985 | D8: Louisiana | E8: South | F8: Small Market | G8: Beans | H8: Coffee | I8: Colombian | J8: Regular | K8: 845 | L8: 13 | M8: 128 | N8: 49 | O8: 25 | P8: 68 | Q8: 0.5313 | R8: 140 | S8: 50 | T8: 70 | U8: 0.5 | V8: -2
A9: TXN-00008 | B9: 45295 | C9: 360 | D9: Washington | E9: West | F9: Small Market | G9: Beans | H9: Espresso | I9: Decaf Espresso | J9: Decaf | K9: 1079 | L9: 24 | M9: 188 | N9: 80 | O9: 45 | P9: 76 | Q9: 0.4043 | R9: 170 | S9: 70 | T9: 60 | U9: 0.3529 | V9: 16
A10: TXN-00009 | B10: 45296 | C10: 715 | D10: Wisconsin | E10: Central | F10: Small Market | G10: Beans | H10: Espresso | I10: Decaf Espresso | J10: Decaf | K10: 573 | L10: 7 | M10: 51 | N10: 22 | O10: 19 | P10: 10 | Q10: 0.1961 | R10: 70 | S10: 20 | T10: 50 | U10: 0.7143 | V10: -40
A11: TXN-00010 | B11: 45296 | C11: 314 | D11: Missouri | E11: Central | F11: Small Market | G11: Leaves | H11: Tea | I11: Green Tea | J11: Regular | K11: 243 | L11: 12 | M11: 74 | N11: 33 | O11: 45 | P11: -4 | Q11: -0.0541 | R11: 60 | S11: 20 | T11: 0 | U11: 0 | V11: -4
A12: TXN-00011 | B12: 45296 | C12: 985 | D12: Louisiana | E12: South | F12: Small Market | G12: Leaves | H12: Herbal Tea | I12: Chamomile | J12: Decaf | K12: 540 | L12: 31 | M12: 228 | N12: 94 | O12: 43 | P12: 114 | Q12: 0.5 | R12: 190 | S12: 80 | T12: 70 | U12: 0.3684 | V12: 44
A13: TXN-00012 | B13: 45298 | C13: 209 | D13: California | E13: West | F13: Major Market | G13: Leaves | H13: Tea | I13: Green Tea | J13: Regular | K13: 659 | L13: 24 | M13: 201 | N13: 75 | O13: 55 | P13: 88 | Q13: 0.4378 | R13: 130 | S13: 50 | T13: 40 | U13: 0.3077 | V13: 48
... A144: TXN-00143 | B144: 45341 | C144: 203 | D144: Connecticut | E144: East | F144: Small Market | G144: Beans | H144: Coffee | I144: Colombian | J144: Regular | K144: 1134 | L144: 42 | M144: 346 | N144: 130 | O144: 73 | P144: 181 | Q144: 0.5231 | R144: 290 | S144: 110 | T144: 130 | U144: 0.4483 | V144: 51
A145: TXN-00144 | B145: 45342 | C145: 262 | D145: Wisconsin | E145: Central | F145: Small Market | G145: Leaves | H145: Herbal Tea | I145: Lemon | J145: Decaf | K145: 851 | L145: 13 | M145: 118 | N145: 48 | O145: 25 | P145: 45 | Q145: 0.3814 | R145: 90 | S145: 30 | T145: 60 | U145: 0.6667
A146: TXN-00145 | B146: 45342 | C146: 361 | D146: Texas | E146: South | F146: Major Market | G146: Beans | H146: Espresso | I146: Caffe Latte | J146: Regular | K146: -1239 | L146: 22 | M146: 179 | N146: 67 | O146: 54 | P146: 70 | Q146: 0.3911 | R146: 120 | S146: 50 | T146: 30 | U146: 0.25 | V146: 40
A147: TXN-00146 | B147: 45342 | C147: 509 | D147: Washington | E147: West | F147: Small Market | G147: Leaves | H147: Herbal Tea | I147: Chamomile | J147: Decaf | K147: 1166 | L147: 37 | M147: 289 | N147: 115 | O147: 69 | P147: 105 | Q147: 0.3633 | R147: 260 | S147: 100 | T147: 110 | U147: 0.4231 | V147: -5
A148: TXN-00147 | B148: 45343 | C148: 702 | D148: Nevada | E148: West | F148: Small Market | G148: Beans | H148: Espresso | I148: Caffe Latte | J148: Regular | K148: 344 | L148: 0 | M148: 43 | N148: 0 | O148: 12 | P148: 31 | Q148: 0.7209 | R148: 40 | S148: 0 | T148: 30 | U148: 0.75 | V148: 1
A149: TXN-00148 | B149: 45343 | C149: 203 | D149: Connecticut | E149: East | F149: Small Market | G149: Leaves | H149: Tea | I149: Green Tea | J149: Regular | K149: 806 | L149: 6 | M149: 64 | N149: 24 | O149: 18 | P149: 27 | Q149: 0.4219 | R149: 60 | S149: 20 | T149: 40 | U149: 0.6667 | V149: -13
A150: TXN-00149 | B150: 45343 | C150: 915 | D150: Texas | E150: South | F150: Major Market | G150: Beans | H150: Espresso | I150: Caffe Mocha | J150: Regular | K150: 930 | L150: 33 | M150: 309 | N150: 118 | O150: 45 | P150: 188 | Q150: 0.6084 | R150: 220 | S150: 90 | T150: 100 | U150: 0.4545 | V150: 88
A151: TXN-00150 | B151: 45343 | C151: 641 | D151: Iowa | E151: Central | F151: Small Market | G151: Leaves | H151: Herbal Tea | I151: Chamomile | J151: Decaf | K151: 1691 | L151: 75 | M151: 567 | N151: 228 | O151: 108 | P151: 291 | Q151: 0.5132 | R151: 490 | S151: 210 | T151: 180 | U151: 0.3673 | V151: 111
A152: TXN-00151 | B152: 45344 | C152: 760 | D152: California | E152: West | F152: Major Market | G152: Leaves | H152: Tea | I152: Earl Grey | J152: Regular | K152: 589 | L152: 14 | M152: 131 | N152: 50 | O152: 26 | P152: 70 | Q152: 0.5344 | R152: 80 | S152: 30 | T152: 40 | U152: 0.5 | V152: 30
A153: TXN-00152 | B153: 45344 | C153: 775 | D153: Nevada | E153: West | F153: Small Market | G153: Beans | H153: Espresso | I153: Caffe Mocha | J153: Regular | K153: 848 | L153: 4 | M153: 42 | N153: 15 | O153: 15 | P153: 13 | Q153: 0.3095 | R153: 30 | S153: 10 | T153: 10 | U153: 0.3333 | V153: 3
A154: TXN-00153 | B154: 45345 | C154: 505 | D154: New Mexico | E154: South | F154: Small Market | G154: Beans | H154: Espresso | I154: Caffe Latte | J154: Regular | K154: -522 | L154: 12 | M154: 81 | N154: 34 | O154: 46 | P154: -6 | Q154: -0.0741 | R154: 50 | S154: 20 | T154: -10 | U154: -0.2 | V154: 4
A155: TXN-00154 | B155: 45345 | C155: 435 | D155: Utah | E155: West | F155: Small Market | G155: Beans | H155: Coffee | I155: Colombian | J155: Regular | K155: 392 | L155: 16 | M155: 121 | N155: 49 | O155: 44 | P155: 31 | Q155: 0.2562 | R155: 130 | S155: 50 | T155: 50 | U155: 0.3846 | V155: -19
A156: TXN-00155 | B156: 45345 | C156: 918 | D156: Oklahoma | E156: South | F156: Small Market | G156: Beans | H156: Espresso | I156: Caffe Latte | J156: Regular | K156: -2248 | L156: 41 | M156: 341 | N156: 134 | O156: 65 | P156: 180 | Q156: 0.5279 | R156: 240 | S156: 100 | T156: 90 | U156: 0.375 | V156: 90
A157: TXN-00156 | B157: 45345 | C157: 978 | D157: Massachusetts | E157: East | F157: Major Market | G157: Beans | H157: Coffee | I157: Colombian | J157: Regular | K157: -3287 | L157: 24 | M157: 454 | N157: 75 | O157: 55 | P157: 324 | Q157: 0.7137 | R157: 400 | S157: 60 | T157: 300 | U157: 0.75 | V157: 24
... A415: TXN-00414 | B415: 45431 | C415: 918 | D415: Oklahoma | E415: South | F415: Small Market | G415: Beans | H415: Espresso | I415: Decaf Espresso | J415: Decaf | K415: 817 | L415: 29 | M415: 236 | N415: 88 | O415: 61 | P415: 107 | Q415: 0.4534 | R415: 170 | S415: 60 | T415: 60 | U415: 0.3529 | V415: 47
A416: TXN-00415 | B416: 45431 | C416: 775 | D416: Nevada | E416: West | F416: Small Market | G416: Leaves | H416: Tea | I416: Green Tea | J416: Regular | K416: 8252 | L416: 111 | M416: 31 | N416: 294 | O416: 145 | P416: -408 | Q416: -13.1613 | R416: 0 | S416: 210 | T416: -320 | U416: #DIV/0! | V416: -88
A417: TXN-00416 | B417: 45432 | C417: 435 | D417: Utah | E417: West | F417: Small Market | G417: Beans | H417: Coffee | I417: Colombian | J417: Regular | K417: 380 | L417: 17 | M417: 124 | N417: 53 | O417: 44 | P417: 27 | Q417: 0.2177 | R417: 140 | S417: 60 | T417: 50 | U417: 0.3571 | V417: -23
A418: TXN-00417 | B418: 45432 | C418: 234 | D418: Ohio | E418: Central | F418: Major Market | G418: Leaves | H418: Tea | I418: Darjeeling | J418: Regular | K418: 788 | L418: 27 | M418: 205 | N418: 82 | O418: 58 | P418: 65 | Q418: 0.3171 | R418: 140 | S418: 50 | T418: 60 | U418: 0.4286 | V418: 5
A419: TXN-00418 | B419: 45433 | C419: 603 | D419: New Hampshire | E419: East | F419: Small Market | G419: Beans | H419: Coffee | I419: Colombian | J419: Regular | K419: 447 | L419: 14 | M419: 121 | N419: 45 | O419: 45 | P419: 36 | Q419: 0.2975 | R419: 90 | S419: 30 | T419: 50 | U419: 0.5556 | V419: -14
A420: TXN-00419 | B420: 45433 | C420: 323 | D420: California | E420: West | F420: Major Market | G420: Leaves | H420: Herbal Tea | I420: Mint | J420: Decaf | K420: 536 | L420: 13 | M420: 98 | N420: 40 | O420: 25 | P420: 40 | Q420: 0.4082 | R420: 80 | S420: 30 | T420: 30 | U420: 0.375 | V420: 10
A421: TXN-00420 | B421: 45433 | C421: 225 | D421: Louisiana | E421: South | F421: Small Market | G421: Beans | H421: Coffee | I421: Decaf Irish Cream | J421: Decaf | K421: 851 | L421: 13 | M421: 118 | N421: 48 | O421: 25 | P421: 45 | Q421: 0.3814 | R421: 160 | S421: 70 | T421: 80 | U421: 0.5 | V421: -35
A422: TXN-00421 | B422: 45434 | C422: 318 | D422: Louisiana | E422: South | F422: Small Market | G422: Beans | H422: Espresso | I422: Caffe Mocha | J422: Regular | K422: 321 | L422: 16 | M422: 150 | N422: 53 | O422: 39 | P422: 73 | Q422: 0.4867 | R422: 100 | S422: 40 | T422: 30 | U422: 0.3 | V422: 43
A423: TXN-00422 | B423: 45434 | C423: 360 | D423: Washington | E423: West | F423: Small Market | G423: Leaves | H423: Tea | I423: Earl Grey | J423: Regular | K423: 449 | L423: 14 | M423: 113 | N423: 46 | O423: 36 | P423: 31 | Q423: 0.2743 | R423: 50 | S423: 20 | T423: 30 | U423: 0.6 | V423: 1
A424: TXN-00423 | B424: 45434 | C424: 503 | D424: Oregon | E424: West | F424: Small Market | G424: Leaves | H424: Herbal Tea | I424: Chamomile | J424: Decaf | K424: 823 | L424: 7 | M424: 63 | N424: 25 | O424: 19 | P424: 19 | Q424: 0.3016 | R424: 50 | S424: 20 | T424: 20 | U424: 0.4 | V424: -1
A425: TXN-00424 | B425: 45434 | C425: 650 | D425: California | E425: West | F425: Major Market | G425: Leaves | H425: Tea | I425: Green Tea | J425: Regular | K425: 659 | L425: 24 | M425: 189 | N425: 75 | O425: 55 | P425: 59 | Q425: 0.3122 | R425: 130 | S425: 50 | T425: 40 | U425: 0.3077 | V425: 19
A426: TXN-00425 | B426: 45435 | C426: 435 | D426: Utah | E426: West | F426: Small Market | G426: Leaves | H426: Herbal Tea | I426: Chamomile | J426: Decaf | K426: 316 | L426: 14 | M426: 120 | N426: 46 | O426: 37 | P426: 45 | Q426: 0.375 | R426: 100 | S426: 40 | T426: 30 | U426: 0.3 | V426: 15
A427: TXN-00426 | B427: 45435 | C427: 641 | D427: Iowa | E427: Central | F427: Small Market | G427: Beans | H427: Coffee | I427: Amaretto | J427: Regular | K427: 851 | L427: 4 | M427: 41 | N427: 16 | O427: 15 | P427: 10 | Q427: 0.2439 | R427: 40 | S427: 10 | T427: 20 | U427: 0.5 | V427: -10
...

Sheet coffe shop project(excel)
B1: Coffee Shop Performance
B2: FY 2024
B4: Total Revenue | D4: Total Profit | F4: Profit Margin
B5: =SUM('coffee shop project'!M:M) -> 202895 | D5: =SUM('coffee shop project'!P:P) -> 64311 | F5: =SUM('coffee shop project'!P:P)/SUM('coffee shop project'!M:M) -> 0.3169669
B8: Sale Achievment | D8: Profit Achievment | F8: Transaction
B9: =SUM('coffee shop project'!M:M)/SUM('coffee shop project'!R:R) -> 1.1338717 | D9: =SUM('coffee shop project'!P:P)/SUM('coffee shop project'!T:T) -> 1.0064319 | F9: =ROWS('coffee shop project'!A2:A1063) -> 1062
B12: Budget VS Actual variance
B13: Metric | C13: Budget | D13: Actuall | E13: Variance $ | F13: Variance % | G13: Status
B14: Revenue | C14: =SUM('coffee shop project'!R:R) -> 178940 | D14: =SUM('coffee shop project'!M:M) -> 202895 | E14: =D14-C14 -> 23955 | F14: =E14/C14 -> 0.13387169 | G14: Above
B15: Profit | C15: =SUM('coffee shop project'!T:T) -> 63900 | D15: =SUM('coffee shop project'!P:P) -> 64311 | E15: =D15-C15 -> 411 | F15: =E15/D15 -> 0.0063908196 | G15: On Target
B16: Cogs | C16: =SUM('coffee shop project'!S:S) -> 76120 | D16: =SUM('coffee shop project'!N:N) -> 87508 | E16: =D16-C16 -> 11388 | F16: =E16/D16 -> 0.13013667 | G16: Above
B19: Quartrly Summary(2024) | H19: Quartrly Forcast (2025)
C20: 1 | D20: 2 | E20: 3 | F20: 4 | H20: 5 | I20: 6 | J20: 7 | K20: 8
B21: Revenue | C21: =SUMIFS('coffee shop project'!M:M,'coffee shop project'!B:B, ">=1/1/2024",'coffee shop project'!B:B, "<=03/31/2024") -> 49221 | D21: =SUMIFS('coffee shop project'!M:M,'coffee shop project'!B:B, ">=4/1/2024",'coffee shop project'!B:B, "<=06/30/2024") -> 54512 | E21: =SUMIFS('coffee shop project'!M:M,'coffee shop project'!B:B, ">=7/1/2024",'coffee shop project'!B:B, "<=09/30/2024") -> 47823 | F21: =SUMIFS('coffee shop project'!M:M,'coffee shop project'!B:B,">=10/1/2024",'coffee shop project'!B:B,"<=12/31/2024") -> 51339 | H21: =_xlfn.FORECAST.LINEAR(H20,C21:F21,C20:F20) -> 50640 | I21: =_xlfn.FORECAST.LINEAR(I20,C21:F21,C20:F20) -> 50606.5 | J21: =_xlfn.FORECAST.LINEAR(J20,C21:F21,C20:F20) -> 50573 | K21: =_xlfn.FORECAST.LINEAR(K20,C21:F21,C20:F20) -> 50539.5
B22: Profit | C22: =SUMIFS('coffee shop project'!P:P,'coffee shop project'!B:B, ">=1/1/2024",'coffee shop project'!B:B, "<=03/31/2024") -> 16298 | D22: =SUMIFS('coffee shop project'!P:P,'coffee shop project'!B:B, ">=4/1/2024",'coffee shop project'!B:B, "<=06/30/2024") -> 17103 | E22: =SUMIFS('coffee shop project'!P:P,'coffee shop project'!B:B, ">=7/1/2024",'coffee shop project'!B:B, "<=09/30/2024") -> 14894 | F22: =SUMIFS('coffee shop project'!P:P,'coffee shop project'!B:B,">=10/1/2024",'coffee shop project'!B:B,"<=12/31/2024") -> 16016 | H22: =_xlfn.FORECAST.LINEAR(H20,C22:F22,C20:F20) -> 15314 | I22: =_xlfn.FORECAST.LINEAR(I20,C22:F22,C20:F20) -> 15008.5 | J22: =_xlfn.FORECAST.LINEAR(J20,C22:F22,C20:F20) -> 14703 | K22: =_xlfn.FORECAST.LINEAR(K20,C22:F22,C20:F20) -> 14397.5
B23: Cogs | C23: =SUMIFS('coffee shop project'!N:N,'coffee shop project'!B:B, ">=1/1/2024",'coffee shop project'!B:B, "<=03/31/2024") -> 20911 | D23: =SUMIFS('coffee shop project'!N:N,'coffee shop project'!B:B, ">=4/1/2024",'coffee shop project'!B:B, "<=06/30/2024") -> 23618 | E23: =SUMIFS('coffee shop project'!N:N,'coffee shop project'!B:B, ">=7/1/2024",'coffee shop project'!B:B, "<=09/30/2024") -> 20589 | F23: =SUMIFS('coffee shop project'!N:N,'coffee shop project'!B:B,">=10/1/2024",'coffee shop project'!B:B,"<=12/31/2024") -> 22390 | H23: =_xlfn.FORECAST.LINEAR(H20,C23:F23,C20:F20) -> 22229 | I23: =_xlfn.FORECAST.LINEAR(I20,C23:F23,C20:F20) -> 22369.8 | J23: =_xlfn.FORECAST.LINEAR(J20,C23:F23,C20:F20) -> 22510.6 | K23: =_xlfn.FORECAST.LINEAR(K20,C23:F23,C20:F20) -> 22651.4
B26: TOP 5 Products
C27: Column Labels
C28: Colombian | D28: Lemon | E28: Caffe Mocha | F28: Chamomile | G28: Decaf Espresso | H28: Grand Total
B29: Sum of Sales | C29: 30761 | D29: 24048 | E29: 21716 | F29: 19295 | G29: 18888 | H29: 114708
B32: TOP 5 STATES
C33: Column Labels
C34: California | D34: New York | E34: Illinois | F34: Nevada | G34: Iowa | H34: Grand Total
B35: Sum of Sales | C35: 23032 | D35: 17731 | E35: 16812 | F35: 14822 | G35: 13359 | H35: 85756
B38: Key Insights
B40: Revenue Trends | D40: Revenue Exceeded target by 13.39%
B41: Quartrly Performance | D41: Revenue peaks on Q2
B42: Product Performance | D42: Colombian Coffee genereted the highest revenue
